Workbook

Sheet 01_RAW
A1: Transaction ID | B1: Date | C1: Customer ID | D1: Gender | E1: Age | F1: Product Category | G1: Quantity | H1: Price per Unit | I1: Total Amount | J1: Age_Group | K1: Month | L1: Year | M1: Quarter
A2: 1 | B2: 45254 | C2: CUST001 | D2: Male | E2: 34 | F2: Beauty | G2: 3 | H2: 50 | I2: 150 | J2: =IF(D2<30,"18-29",IF(D2<45,"30-44",IF(D2<60,"45-59","60+"))) -> 60+ | K2: =TEXT(B2,"AAAA-MM") -> viernes-11 | L2: =YEAR(B2) -> 2023 | M2: ="T"&INT((MONTH(B2)-1)/3+1)&"-"&YEAR(B2) -> T4-2023
A3: 2 | B3: 44984 | C3: CUST002 | D3: Female | E3: 26 | F3: Clothing | G3: 2 | H3: 500 | I3: 1000 | J3: =IF(D3<30,"18-29",IF(D3<45,"30-44",IF(D3<60,"45-59","60+"))) -> 60+ | K3: =TEXT(B3,"AAAA-MM") -> lunes-02 | L3: =YEAR(B3) -> 2023 | M3: ="T"&INT((MONTH(B3)-1)/3+1)&"-"&YEAR(B3) -> T1-2023
A4: 3 | B4: 44939 | C4: CUST003 | D4: Male | E4: 50 | F4: Electronics | G4: 1 | H4: 30 | I4: 30 | J4: =IF(D4<30,"18-29",IF(D4<45,"30-44",IF(D4<60,"45-59","60+"))) -> 60+ | K4: =TEXT(B4,"AAAA-MM") -> viernes-01 | L4: =YEAR(B4) -> 2023 | M4: ="T"&INT((MONTH(B4)-1)/3+1)&"-"&YEAR(B4) -> T1-2023
A5: 4 | B5: 45067 | C5: CUST004 | D5: Male | E5: 37 | F5: Clothing | G5: 1 | H5: 500 | I5: 500 | J5: =IF(D5<30,"18-29",IF(D5<45,"30-44",IF(D5<60,"45-59","60+"))) -> 60+ | K5: =TEXT(B5,"AAAA-MM") -> domingo-05 | L5: =YEAR(B5) -> 2023 | M5: ="T"&INT((MONTH(B5)-1)/3+1)&"-"&YEAR(B5) -> T2-2023
A6: 5 | B6: 45052 | C6: CUST005 | D6: Male | E6: 30 | F6: Beauty | G6: 2 | H6: 50 | I6: 100 | J6: =IF(D6<30,"18-29",IF(D6<45,"30-44",IF(D6<60,"45-59","60+"))) -> 60+ | K6: =TEXT(B6,"AAAA-MM") -> sábado-05 | L6: =YEAR(B6) -> 2023 | M6: ="T"&INT((MONTH(B6)-1)/3+1)&"-"&YEAR(B6) -> T2-2023
A7: 6 | B7: 45041 | C7: CUST006 | D7: Female | E7: 45 | F7: Beauty | G7: 1 | H7: 30 | I7: 30 | J7: =IF(D7<30,"18-29",IF(D7<45,"30-44",IF(D7<60,"45-59","60+"))) -> 60+ | K7: =TEXT(B7,"AAAA-MM") -> martes-04 | L7: =YEAR(B7) -> 2023 | M7: ="T"&INT((MONTH(B7)-1)/3+1)&"-"&YEAR(B7) -> T2-2023
A8: 7 | B8: 44998 | C8: CUST007 | D8: Male | E8: 46 | F8: Clothing | G8: 2 | H8: 25 | I8: 50 | J8: =IF(D8<30,"18-29",IF(D8<45,"30-44",IF(D8<60,"45-59","60+"))) -> 60+ | K8: =TEXT(B8,"AAAA-MM") -> lunes-03 | L8: =YEAR(B8) -> 2023 | M8: ="T"&INT((MONTH(B8)-1)/3+1)&"-"&YEAR(B8) -> T1-2023
A9: 8 | B9: 44979 | C9: CUST008 | D9: Male | E9: 30 | F9: Electronics | G9: 4 | H9: 25 | I9: 100 | J9: =IF(D9<30,"18-29",IF(D9<45,"30-44",IF(D9<60,"45-59","60+"))) -> 60+ | K9: =TEXT(B9,"AAAA-MM") -> miércoles-02 | L9: =YEAR(B9) -> 2023 | M9: ="T"&INT((MONTH(B9)-1)/3+1)&"-"&YEAR(B9) -> T1-2023
A10: 9 | B10: 45273 | C10: CUST009 | D10: Male | E10: 63 | F10: Electronics | G10: 2 | H10: 300 | I10: 600 | J10: =IF(D10<30,"18-29",IF(D10<45,"30-44",IF(D10<60,"45-59","60+"))) -> 60+ | K10: =TEXT(B10,"AAAA-MM") -> miércoles-12 | L10: =YEAR(B10) -> 2023 | M10: ="T"&INT((MONTH(B10)-1)/3+1)&"-"&YEAR(B10) -> T4-2023
A11: 10 | B11: 45206 | C11: CUST010 | D11: Female | E11: 52 | F11: Clothing | G11: 4 | H11: 50 | I11: 200 | J11: =IF(D11<30,"18-29",IF(D11<45,"30-44",IF(D11<60,"45-59","60+"))) -> 60+ | K11: =TEXT(B11,"AAAA-MM") -> sábado-10 | L11: =YEAR(B11) -> 2023 | M11: ="T"&INT((MONTH(B11)-1)/3+1)&"-"&YEAR(B11) -> T4-2023
A12: 11 | B12: 44971 | C12: CUST011 | D12: Male | E12: 23 | F12: Clothing | G12: 2 | H12: 50 | I12: 100 | J12: =IF(D12<30,"18-29",IF(D12<45,"30-44",IF(D12<60,"45-59","60+"))) -> 60+ | K12: =TEXT(B12,"AAAA-MM") -> martes-02 | L12: =YEAR(B12) -> 2023 | M12: ="T"&INT((MONTH(B12)-1)/3+1)&"-"&YEAR(B12) -> T1-2023
A13: 12 | B13: 45229 | C13: CUST012 | D13: Male | E13: 35 | F13: Beauty | G13: 3 | H13: 25 | I13: 75 | J13: =IF(D13<30,"18-29",IF(D13<45,"30-44",IF(D13<60,"45-59","60+"))) -> 60+ | K13: =TEXT(B13,"AAAA-MM") -> lunes-10 | L13: =YEAR(B13) -> 2023 | M13: ="T"&INT((MONTH(B13)-1)/3+1)&"-"&YEAR(B13) -> T4-2023
... A1001: 1000 | B1001: 45028 | C1001: CUST1000 | D1001: Male | E1001: 47 | F1001: Electronics | G1001: 4 | H1001: 30 | I1001: 120 | J1001: =IF(D1001<30,"18-29",IF(D1001<45,"30-44",IF(D1001<60,"45-59","60+"))) -> 60+ | K1001: =TEXT(B1001,"AAAA-MM") -> miércoles-04 | L1001: =YEAR(B1001) -> 2023 | M1001: ="T"&INT((MONTH(B1001)-1)/3+1)&"-"&YEAR(B1001) -> T2-2023
B1003: =MIN(B2:B1001) -> 44927 | C1003: {=SUM(1/COUNTIF(C2:C1001,C2:C1001))} -> 1000
B1004: =MAX(B2:B1001) -> 45292

Sheet 02_CLEAN
A1: Transaction ID | B1: Date | C1: Customer ID | D1: Gender | E1: Age | F1: Product Category | G1: Quantity | H1: Price per Unit | I1: Total Amount | J1: Age_Group | K1: Month | L1: Year | M1: Quarter
A2: 1 | B2: 45254 | C2: CUST001 | D2: Male | E2: 34 | F2: Beauty | G2: 3 | H2: 50 | I2: 150 | J2: =IF(D2<30,"18-29",IF(D2<45,"30-44",IF(D2<60,"45-59","60+"))) -> 60+ | K2: =TEXT(B2,"AAAA-MM") -> viernes-11 | L2: =YEAR(B2) -> 2023 | M2: ="T"&INT((MONTH(B2)-1)/3+1)&"-"&YEAR(B2) -> T4-2023
A3: 2 | B3: 44984 | C3: CUST002 | D3: Female | E3: 26 | F3: Clothing | G3: 2 | H3: 500 | I3: 1000 | J3: =IF(D3<30,"18-29",IF(D3<45,"30-44",IF(D3<60,"45-59","60+"))) -> 60+ | K3: =TEXT(B3,"AAAA-MM") -> lunes-02 | L3: =YEAR(B3) -> 2023 | M3: ="T"&INT((MONTH(B3)-1)/3+1)&"-"&YEAR(B3) -> T1-2023
A4: 3 | B4: 44939 | C4: CUST003 | D4: Male | E4: 50 | F4: Electronics | G4: 1 | H4: 30 | I4: 30 | J4: =IF(D4<30,"18-29",IF(D4<45,"30-44",IF(D4<60,"45-59","60+"))) -> 60+ | K4: =TEXT(B4,"AAAA-MM") -> viernes-01 | L4: =YEAR(B4) -> 2023 | M4: ="T"&INT((MONTH(B4)-1)/3+1)&"-"&YEAR(B4) -> T1-2023
A5: 4 | B5: 45067 | C5: CUST004 | D5: Male | E5: 37 | F5: Clothing | G5: 1 | H5: 500 | I5: 500 | J5: =IF(D5<30,"18-29",IF(D5<45,"30-44",IF(D5<60,"45-59","60+"))) -> 60+ | K5: =TEXT(B5,"AAAA-MM") -> domingo-05 | L5: =YEAR(B5) -> 2023 | M5: ="T"&INT((MONTH(B5)-1)/3+1)&"-"&YEAR(B5) -> T2-2023
A6: 5 | B6: 45052 | C6: CUST005 | D6: Male | E6: 30 | F6: Beauty | G6: 2 | H6: 50 | I6: 100 | J6: =IF(D6<30,"18-29",IF(D6<45,"30-44",IF(D6<60,"45-59","60+"))) -> 60+ | K6: =TEXT(B6,"AAAA-MM") -> sábado-05 | L6: =YEAR(B6) -> 2023 | M6: ="T"&INT((MONTH(B6)-1)/3+1)&"-"&YEAR(B6) -> T2-2023
A7: 6 | B7: 45041 | C7: CUST006 | D7: Female | E7: 45 | F7: Beauty | G7: 1 | H7: 30 | I7: 30 | J7: =IF(D7<30,"18-29",IF(D7<45,"30-44",IF(D7<60,"45-59","60+"))) -> 60+ | K7: =TEXT(B7,"AAAA-MM") -> martes-04 | L7: =YEAR(B7) -> 2023 | M7: ="T"&INT((MONTH(B7)-1)/3+1)&"-"&YEAR(B7) -> T2-2023
A8: 7 | B8: 44998 | C8: CUST007 | D8: Male | E8: 46 | F8: Clothing | G8: 2 | H8: 25 | I8: 50 | J8: =IF(D8<30,"18-29",IF(D8<45,"30-44",IF(D8<60,"45-59","60+"))) -> 60+ | K8: =TEXT(B8,"AAAA-MM") -> lunes-03 | L8: =YEAR(B8) -> 2023 | M8: ="T"&INT((MONTH(B8)-1)/3+1)&"-"&YEAR(B8) -> T1-2023
A9: 8 | B9: 44979 | C9: CUST008 | D9: Male | E9: 30 | F9: Electronics | G9: 4 | H9: 25 | I9: 100 | J9: =IF(D9<30,"18-29",IF(D9<45,"30-44",IF(D9<60,"45-59","60+"))) -> 60+ | K9: =TEXT(B9,"AAAA-MM") -> miércoles-02 | L9: =YEAR(B9) -> 2023 | M9: ="T"&INT((MONTH(B9)-1)/3+1)&"-"&YEAR(B9) -> T1-2023
A10: 9 | B10: 45273 | C10: CUST009 | D10: Male | E10: 63 | F10: Electronics | G10: 2 | H10: 300 | I10: 600 | J10: =IF(D10<30,"18-29",IF(D10<45,"30-44",IF(D10<60,"45-59","60+"))) -> 60+ | K10: =TEXT(B10,"AAAA-MM") -> miércoles-12 | L10: =YEAR(B10) -> 2023 | M10: ="T"&INT((MONTH(B10)-1)/3+1)&"-"&YEAR(B10) -> T4-2023
A11: 10 | B11: 45206 | C11: CUST010 | D11: Female | E11: 52 | F11: Clothing | G11: 4 | H11: 50 | I11: 200 | J11: =IF(D11<30,"18-29",IF(D11<45,"30-44",IF(D11<60,"45-59","60+"))) -> 60+ | K11: =TEXT(B11,"AAAA-MM") -> sábado-10 | L11: =YEAR(B11) -> 2023 | M11: ="T"&INT((MONTH(B11)-1)/3+1)&"-"&YEAR(B11) -> T4-2023
A12: 11 | B12: 44971 | C12: CUST011 | D12: Male | E12: 23 | F12: Clothing | G12: 2 | H12: 50 | I12: 100 | J12: =IF(D12<30,"18-29",IF(D12<45,"30-44",IF(D12<60,"45-59","60+"))) -> 60+ | K12: =TEXT(B12,"AAAA-MM") -> martes-02 | L12: =YEAR(B12) -> 2023 | M12: ="T"&INT((MONTH(B12)-1)/3+1)&"-"&YEAR(B12) -> T1-2023
A13: 12 | B13: 45229 | C13: CUST012 | D13: Male | E13: 35 | F13: Beauty | G13: 3 | H13: 25 | I13: 75 | J13: =IF(D13<30,"18-29",IF(D13<45,"30-44",IF(D13<60,"45-59","60+"))) -> 60+ | K13: =TEXT(B13,"AAAA-MM") -> lunes-10 | L13: =YEAR(B13) -> 2023 | M13: ="T"&INT((MONTH(B13)-1)/3+1)&"-"&YEAR(B13) -> T4-2023
... A1001: 1000 | B1001: 45028 | C1001: CUST1000 | D1001: Male | E1001: 47 | F1001: Electronics | G1001: 4 | H1001: 30 | I1001: 120 | J1001: =IF(D1001<30,"18-29",IF(D1001<45,"30-44",IF(D1001<60,"45-59","60+"))) -> 60+ | K1001: =TEXT(B1001,"AAAA-MM") -> miércoles-04 | L1001: =YEAR(B1001) -> 2023 | M1001: ="T"&INT((MONTH(B1001)-1)/3+1)&"-"&YEAR(B1001) -> T2-2023

Sheet 03_KPIs
A1: KPI | B1: Definición | C1: Cálculo / Columna origen
A2: Total de transacciones | B2: Conteo total de filas validas | C2: =COUNTA('02_CLEAN'!A2:A1001) -> 1000
A3: Clientes unicos | B3: Numero de Customer ID distintos | C3: {=SUM(1/COUNTIF(retail_sales_dataset[Customer ID],retail_sales_dataset[Customer ID]))} -> 1000
A4: Ingreso total | B4: Suma de Total Amount | C4: =SUM('02_CLEAN'!I2:I1001) -> 456000
A5: Ticket promedio | B5: Promedio de Total Amount | C5: =AVERAGE('02_CLEAN'!I2:I1001) -> 456
A6: Unidades vendidas | B6: Suma de Quantity | C6: =SUM('02_CLEAN'!G2:G1001) -> 2514
A7: Ingreso por categoria | B7: Beauty | C7: =SUMIF('01_RAW'!F:F,B7,'01_RAW'!I:I) -> 143515
B8: Clothing | C8: =SUMIF('01_RAW'!F:F,B8,'01_RAW'!I:I) -> 155580
B9: Electronics | C9: =SUMIF('01_RAW'!F:F,B9,'01_RAW'!I:I) -> 156905
A10: Ingreso por genero | B10: Male | C10: =SUMIF('01_RAW'!D:D,B10,'01_RAW'!I:I) -> 223160
B11: Female | C11: =SUMIF('01_RAW'!D:D,B11,'01_RAW'!I:I) -> 232840

Sheet 04_PIVOT
B2: Ingreso por categoria de producto y genero | G2: Ventas por mes (serie temporal basica)
B4: Categoria/Genero | C4: Genero | G4: Categoria | H4: Suma de Total Amount | I4: Cuenta de Transaction ID
B5: Categoria | C5: Female | D5: Male | E5: Total general | G5: domingo-01 | H5: 5810 | I5: 11
B6: Beauty | C6: 74830 | D6: 68685 | E6: 143515 | G6: domingo-02 | H6: 4380 | I6: 12
B7: Clothing | C7: 81275 | D7: 74305 | E7: 155580 | G7: domingo-03 | H7: 2445 | I7: 9
B8: Electronics | C8: 76735 | D8: 80170 | E8: 156905 | G8: domingo-04 | H8: 8195 | I8: 21
B9: Total general | C9: 232840 | D9: 223160 | E9: 456000 | G9: domingo-05 | H9: 5030 | I9: 12
G10: domingo-06 | H10: 6130 | I10: 11
B11: Ingreso por grupo de edad | G11: domingo-07 | H11: 2785 | I11: 9
G12: domingo-08 | H12: 5015 | I12: 9
B13: Categoria | C13: Suma de Total Amount | D13: Promedio de Total Amount2 | E13: Cuenta de Transaction ID | G13: domingo-09 | H13: 1590 | I13: 9
B14: 18 | C14: 11215 | D14: 534.04762 | E14: 21 | G14: domingo-10 | H14: 9525 | I14: 17
B15: 19 | C15: 14870 | D15: 708.09524 | E15: 21 | G15: domingo-11 | H15: 3925 | I15: 8
B16: 20 | C16: 8645 | D16: 411.66667 | E16: 21 | G16: domingo-12 | H16: 3770 | I16: 10
B17: 21 | C17: 12585 | D17: 629.25 | E17: 20 | G17: jueves-01 | H17: 3700 | I17: 8
B18: 22 | C18: 13700 | D18: 507.40741 | E18: 27 | G18: jueves-02 | H18: 2905 | I18: 6
B19: 23 | C19: 8220 | D19: 342.5 | E19: 24 | G19: jueves-03 | H19: 3650 | I19: 9
B20: 24 | C20: 5415 | D20: 361 | E20: 15 | G20: jueves-04 | H20: 6365 | I20: 12
B21: 25 | C21: 9900 | D21: 495 | E21: 20 | G21: jueves-05 | H21: 4320 | I21: 9
B22: 26 | C22: 13980 | D22: 635.45455 | E22: 22 | G22: jueves-06 | H22: 5450 | I22: 14
B23: 27 | C23: 9385 | D23: 408.04348 | E23: 23 | G23: jueves-07 | H23: 3550 | I23: 7
B24: 28 | C24: 8670 | D24: 412.85714 | E24: 21 | G24: jueves-08 | H24: 5140 | I24: 13
B25: 29 | C25: 6570 | D25: 410.625 | E25: 16 | G25: jueves-09 | H25: 2150 | I25: 9
B26: 30 | C26: 9790 | D26: 445 | E26: 22 | G26: jueves-10 | H26: 3605 | I26: 12 | K26: Top 10 clientes por ingreso total
B27: 31 | C27: 10220 | D27: 464.54545 | E27: 22 | G27: jueves-11 | H27: 8565 | I27: 16
B28: 32 | C28: 5550 | D28: 292.10526 | E28: 19 | G28: jueves-12 | H28: 4435 | I28: 8 | K28: Categoria | L28: Suma de Total Amount
B29: 33 | C29: 6240 | D29: 624 | E29: 10 | G29: lunes-01 | H29: 11355 | I29: 16 | K29: CUST015 | L29: 2000
B30: 34 | C30: 16785 | D30: 599.46429 | E30: 28 | G30: lunes-02 | H30: 7180 | I30: 15 | K30: CUST065 | L30: 2000
B31: 35 | C31: 11290 | D31: 513.18182 | E31: 22 | G31: lunes-03 | H31: 4465 | I31: 14 | K31: CUST072 | L31: 2000
B32: 36 | C32: 9105 | D32: 607 | E32: 15 | G32: lunes-04 | H32: 255 | I32: 5 | K32: CUST074 | L32: 2000
B33: 37 | C33: 11650 | D33: 728.125 | E33: 16 | G33: lunes-05 | H33: 9515 | I33: 17 | K33: CUST089 | L33: 2000
B34: 38 | C34: 11100 | D34: 584.21053 | E34: 19 | G34: lunes-06 | H34: 5225 | I34: 11 | K34: CUST093 | L34: 2000
B35: 39 | C35: 4595 | D35: 255.27778 | E35: 18 | G35: lunes-07 | H35: 7290 | I35: 10 | K35: CUST109 | L35: 2000
B36: 40 | C36: 9415 | D36: 392.29167 | E36: 24 | G36: lunes-08 | H36: 4160 | I36: 13 | K36: CUST118 | L36: 2000
B37: 41 | C37: 5650 | D37: 269.04762 | E37: 21 | G37: lunes-09 | H37: 5290 | I37: 9 | K37: CUST124 | L37: 2000
B38: 42 | C38: 8500 | D38: 326.92308 | E38: 26 | G38: lunes-10 | H38: 5175 | I38: 17 | K38: CUST139 | L38: 2000
B39: 43 | C39: 17970 | D39: 579.67742 | E39: 31 | G39: lunes-11 | H39: 4210 | I39: 8 | K39: CUST152 | L39: 2000
B40: 44 | C40: 7560 | D40: 504 | E40: 15 | G40: lunes-12 | H40: 6130 | I40: 11 | K40: CUST155 | L40: 2000
... B60: 64 | C60: 9125 | D60: 294.35484 | E60: 31 | G60: miércoles-08 | H60: 2790 | I60: 8 | K60: CUST592 | L60: 2000
B61: Total general | C61: 456000 | D61: 456 | E61: 1000 | G61: miércoles-09 | H61: 1815 | I61: 6 | K61: CUST595 | L61: 2000
...

Sheet 05_NOTAS
A2: REGISTROS | B2: ='01_RAW'!C1003 -> 1000
A3: FECHA INICIO | B3: ='01_RAW'!B1003 -> 44927
A4: FECHA FIN | B4: ='01_RAW'!B1004 -> 45292
